Workbook

Sheet VERI_TABANI
A1: SABİT SİSTEM PARAMETRELERİ (ARKA PLAN VERİ TABANI - DOKTORA MODELİ v24)
A3: GES Üretim Faktörü (kWh/kW-yıl) | B3: 1675 | C3: kWh/kW-yıl
A4: RES Üretim Faktörü (kWh/kW-yıl) | B4: 2628 | C4: kWh/kW-yıl
A5: GES Kurulum Birim Maliyeti (€/kW) | B5: 592.87 | C5: €/kW
A6: RES Kurulum Birim Maliyeti (€/kW) | B6: 1365.57 | C6: €/kW
A7: Tüketim Mahsuplaşma Fiyatı (≤%100) (€/kWh) | B7: 0.0934 | C7: €/kWh
A8: Şebekeye Satış Fiyatı (>%100) (€/kWh) | B8: 0.0594 | C8: €/kWh
A9: Doğalgaz Fiyatı (€/Sm3) | B9: 0.2746 | C9: €/Sm3
A10: Yeşil H2 Tesis Kurulum Birim Maliyeti (€/kg H2/yıl) | B10: 7.42 | C10: €/kg H2/yıl
A11: Gri H2 Tesis Kurulum Birim Maliyeti (€/kg H2/yıl) | B11: 3.33 | C11: €/kg H2/yıl
A12: H2 Injection Retrofit Maliyeti (€/kg H2/yıl) | B12: 0.343 | C12: €/kg H2/yıl
A13: Türkiye Şebeke Emisyon Faktörü (tCO2/kWh) | B13: 0.0006242 | C13: tCO2/kWh
A14: GES LCA Footprint (tCO2/kWh) | B14: 6e-05 | C14: tCO2/kWh
... A18: Doğalgaz Emisyon Faktörü (tCO2/Sm3) | B18: 0.00202 | C18: tCO2/Sm3
A20: PERİYOT BAZLI DÖNÜŞÜM VERİ KÜMELERİ (2025 – 2053 TAHMİN PROJEKSİYONLARI)
A22: Periyot | B22: Yıl Sayısı | C22: Orijinal Üretim (Ton) | D22: Elektrik Tüketimi (kWh) | E22: Doğalgaz Tüketimi (Sm3) | F22: Hidrojen Tüketimi (kg) | G22: SKDM Karbon Fiyatı (€/tCO2)
A23: 2025 – 2030 | B23: 6 | C23: 4304837.4 | D23: 1.3625871e+09 | E23: 5.2108659e+08 | F23: 10868199 | G23: 106.5
A24: 2031 – 2035 | B24: 5 | C24: 4136473 | D24: 1.3111603e+09 | E24: 5.0004277e+08 | F24: 10429292 | G24: 151.1
A25: 2036 – 2040 | B25: 5 | C25: 4635662.5 | D25: 1.4708613e+09 | E25: 5.5986454e+08 | F25: 11676983 | G25: 205.4
A26: 2041 – 2045 | B26: 5 | C26: 5134852 | D26: 1.6305622e+09 | E26: 6.1968631e+08 | F26: 12924673 | G26: 276.6
A27: 2046 – 2050 | B27: 5 | C27: 5634041.6 | D27: 1.7902632e+09 | E27: 6.7950808e+08 | F27: 14172364 | G27: 369.4
A28: 2051 – 2053 | B28: 3 | C28: 3620035.9 | D28: 1.1508144e+09 | E28: 4.364193e+08 | F28: 9102310 | G28: 390.6
A29: 2025 – 2053 TOPLAM | B29: =SUM(B23:B28) | C29: =SUM(C23:C28) | D29: =SUM(D23:D28) | E29: =SUM(E23:E28) | F29: =SUM(F23:F28) | G29: =AVERAGE(G23:G28)

Sheet DASHBOARD
A1: CAM ENERJİ FABRİKASI - DOKTORA TEZİ KARAR DESTEK VE KONTROL DASHBOARD'U (v24)
A2: SKDM Sürecinde Hibrit Enerji ve Hidrojen Entegrasyonu Bağımsız & Bütünleşik Analiz Mimarisi (v24)
A4: 1. KULLANICI SENARYO SEÇİMLERİ VE HEDEFLER
A5: Hedef Yenilenebilir Elektrik Oranı (%) | B5: 1.12 | C5: Fabrikanın toplam elektrik tüketimine göre hedeflenen yenilenebilir enerji oranı (Örn. %112)
A6: GES Katkı Oranı (% Tüketime Göre) | B6: 0.6 | C6: Toplam tüketimin Güneş Santralinden (GES) karşılanacak yüzdesi
A7: RES Katkı Oranı (% Tüketime Göre) | B7: 0.52 | C7: Toplam tüketimin Rüzgar Santralinden (RES) karşılanacak yüzdesi
A8: Hidrojen Kullanım Durumu / Tipi | B8: 1 | C8: 1 = Yeşil Hidrojen (%20 H2), -1 = Gri Hidrojen (%20 H2), 0 = Hidrojen Yok (%0 H2)
A9: Girilmiş GES + RES Toplamı (%) | B9: =B6+B7 | C9: =IF(ABS((B6+B7)-B5)>0.0001, "⚠️ UYARI: GES + RES Payları Toplamı (" & TEXT(B6+B7, "0.0%") & ") Hedef Orana (" & TEXT(B5, "0.0%") & ") Eşit Değildir!", "✅ ORAN DENGESİ UYUMLU: GES + RES Payı Toplamı Hedef Oran ile Eşittir.")
A10: Master Mod Seçim Şalteri (1=Mod 1, 2=Mod 2, 3=Mod 3) | B10: 1 | C10: 1 = Mod 1 (Enerji Oranı Odaklı), 2 = Mod 2 (Bütçe Odaklı), 3 = Mod 3 (Karbon Hedef Odaklı)
A11: Maksimum Yatırım Bütçesi Kısıtı (€) | B11: 200000000 | C11: Mod 2 için üst yatırım bütçesi limiti (Örn. 200 M€)
A12: Minimum Karbon Engelleme Hedefi (tCO₂) | B12: 5000000 | C12: Mod 3 için alt emisyon azaltım hedefi (Örn. 5 M tCO2)
A14: 2. PERİYOT BAZLI BAĞIMSIZ DAL (GES, RES, H2) VE BÜTÜNLEŞİK SİNERJİ ANALİZİ (v24)
A15: PERİYOT VE TÜKETİM VERİLERİ | D15: 1. DAL: GÜNEŞ ENERJİSİ SANTRALİ (GES) BAĞIMSIZ ANALİZ PANOSU | O15: 2. DAL: RÜZGAR ENERJİSİ SANTRALİ (RES) BAĞIMSIZ ANALİZ PANOSU | Z15: 3. DAL: HİDROJEN ENTEGRASYONU BAĞIMSIZ ANALİZ PANOSU | AK15: 4. DAL: BÜTÜNLEŞİK HİBRİT SİNERJİ PANOSU
A16: Periyot | B16: Toplam Üretim (Ton) | C16: Elektrik Tüketimi (kWh) | D16: GES Üretimi (kWh) | E16: Toplam GES Gücü (kW) | F16: İlave GES Gücü (kW) | G16: İlave GES Yatırımı (€) | H16: GES Mahsuplaşma Tasarrufu (€) | I16: GES Net SKDM Karbon Tasarrufu (€) | J16: GES Toplam Fayda (€) | K16: GES Tekil LCA Oranı (%) | L16: GES Mahsuplaşma Geri Ödeme (Yıl) | M16: GES Karbon Kazancı Geri Ödeme (Yıl) | N16: GES Kollektif Geri Ödeme (Yıl) | O16: RES Üretimi (kWh) | P16: Toplam RES Gücü (kW) | Q16: İlave RES Gücü (kW) | R16: İlave RES Yatırımı (€) | S16: RES Mahsuplaşma Tasarrufu (€) | T16: RES Net SKDM Karbon Tasarrufu (€) | U16: RES Toplam Fayda (€) | V16: RES Tekil LCA Oranı (%) | W16: RES Mahsuplaşma Geri Ödeme (Yıl) | X16: RES Karbon Kazancı Geri Ödeme (Yıl) | Y16: RES Kollektif Geri Ödeme (Yıl) | Z16: Kullanılmayan DG (Sm3) | AA16: H2 Tüketimi (kg) | AB16: H2 Yıllık Kapasitesi (kg/yıl) | AC16: İlave H2 Tesis/Retrofit Yatırımı (€) | AD16: H2 DG Maliyet Kazancı (€) | AE16: H2 Net SKDM Karbon Kazancı (€) | AF16: H2 Toplam Fayda (€) | AG16: H2 Tekil LCA Oranı (%) | AH16: H2 Mahsuplaşma Geri Ödeme (Yıl) | AI16: H2 Karbon Kazancı Geri Ödeme (Yıl) | AJ16: H2 Kollektif Geri Ödeme (Yıl) | AK16: GES Yatırımı (€) | AL16: RES Yatırımı (€) | AM16: H2 Tesis Yatırımı (€) | AN16: Toplam Kümülatif Yatırım (€) | AO16: GES Karbon Kazancı (tCO2) | AP16: RES Karbon Kazancı (tCO2) | AQ16: H2 Karbon Kazancı (tCO2) | AR16: Net Karbon Kazancı (tCO2) | AS16: Net Karbon Kazancı (€) | AT16: Birleşik LCA Oranı (%) | AU16: GES Toplam Faydası (€) | AV16: RES Toplam Faydası (€) | AW16: H2 Toplam Faydası (€) | AX16: Periyot Toplam Net Faydası (€) | AY16: Kollektif Mahsuplaşma Geri Ödeme (Yıl) | AZ16: Kollektif Karbon Kazancı Geri Ödeme (Yıl) | BA16: Kollektif Basit Geri Ödeme Süresi (Yıl)
A17: =VERI_TABANI!A23 | B17: =VERI_TABANI!C23 | C17: =VERI_TABANI!D23 | D17: =C17*DASHBOARD!$B$6 | E17: =(D17/VERI_TABANI!B23)/VERI_TABANI!$B$3 | F17: =E17 | G17: =F17*VERI_TABANI!$B$5 | H17: =MIN(C17, D17)*VERI_TABANI!$B$7 + MAX(0, D17-C17)*VERI_TABANI!$B$8 | I17: =D17*(VERI_TABANI!$B$13-VERI_TABANI!$B$14)*VERI_TABANI!G23 | J17: =H17+I17 | K17: =IFERROR((D17*VERI_TABANI!$B$14)/(D17*VERI_TABANI!$B$13), 0) | L17: =IFERROR(G17/(H17/VERI_TABANI!B23), 0) | M17: =IFERROR(G17/(I17/VERI_TABANI!B23), 0) | N17: =IFERROR(G17/(J17/VERI_TABANI!B23), 0) | O17: =C17*DASHBOARD!$B$7 | P17: =(O17/VERI_TABANI!B23)/VERI_TABANI!$B$4 | Q17: =P17 | R17: =Q17*VERI_TABANI!$B$6 | S17: =MIN(MAX(0, C17-D17), O17)*VERI_TABANI!$B$7 + MAX(0, O17-MAX(0, C17-D17))*VERI_TABANI!$B$8 | T17: =O17*(VERI_TABANI!$B$13-VERI_TABANI!$B$15)*VERI_TABANI!G23 | U17: =S17+T17 | V17: =IFERROR((O17*VERI_TABANI!$B$15)/(O17*VERI_TABANI!$B$13), 0) | W17: =IFERROR(R17/(S17/VERI_TABANI!B23), 0) | X17: =IFERROR(R17/(T17/VERI_TABANI!B23), 0) | Y17: =IFERROR(R17/(U17/VERI_TABANI!B23), 0) | Z17: =IF(ABS(DASHBOARD!$B$8)=1, VERI_TABANI!E23*(1-0.928), 0) | AA17: =IF(ABS(DASHBOARD!$B$8)=1, VERI_TABANI!F23, 0) | AB17: =AA17/VERI_TABANI!B23 | AC17: =IF(DASHBOARD!$B$8=1, AB17*(VERI_TABANI!$B$10+VERI_TABANI!$B$12), IF(DASHBOARD!$B$8=-1, AB17*(VERI_TABANI!$B$11+VERI_TABANI!$B$12), 0)) | AD17: =Z17*VERI_TABANI!$B$9 | AE17: =Z17*0.00206091519919798*VERI_TABANI!G23 | AF17: =AD17+AE17 | AG17: =IFERROR((IF($B$8=1, AA17*VERI_TABANI!B16, IF($B$8=-1, AA17*VERI_TABANI!B17, 0))) / (Z17*VERI_TABANI!B18), 0) | AH17: =IFERROR(AC17/(AD17/VERI_TABANI!B23), 0) | AI17: =IFERROR(AC17/(AE17/VERI_TABANI!B23), 0) | AJ17: =IFERROR(AC17/(AF17/VERI_TABANI!B23), 0) | AK17: =G17 | AL17: =R17 | AM17: =AC17 | AN17: =AK17+AL17+AM17 | AO17: =D17*(VERI_TABANI!$B$13-VERI_TABANI!$B$14) | AP17: =O17*(VERI_TABANI!$B$13-VERI_TABANI!$B$15) | AQ17: =IF($B$8=1, AA17*(0.00202-VERI_TABANI!B16), IF($B$8=-1, AA17*(0.00202-VERI_TABANI!B17), 0)) | AR17: =AO17+AP17+AQ17 | AS17: =I17+T17+AE17 | AT17: =IFERROR((D17*VERI_TABANI!$B$14 + O17*VERI_TABANI!$B$15 + IF($B$8=1, AA17*VERI_TABANI!B16, IF($B$8=-1, AA17*VERI_TABANI!B17, 0))) / ((D17+O17)*VERI_TABANI!$B$13 + Z17*VERI_TABANI!B18), 0) | AU17: =J17 | AV17: =U17 | AW17: =AF17 | AX17: =AU17+AV17+AW17 | AY17: =IFERROR(AN17/((H17+S17+AD17)/VERI_TABANI!B23), 0) | AZ17: =IFERROR(AN17/((I17+T17+AE17)/VERI_TABANI!B23), 0) | BA17: =IFERROR(AN17/(AX17/VERI_TABANI!B23), 0)
A18: =VERI_TABANI!A24 | B18: =VERI_TABANI!C24 | C18: =VERI_TABANI!D24 | D18: =C18*DASHBOARD!$B$6 | E18: =(D18/VERI_TABANI!B24)/VERI_TABANI!$B$3 | F18: =MAX(0, E18-E17) | G18: =F18*VERI_TABANI!$B$5 | H18: =MIN(C18, D18)*VERI_TABANI!$B$7 + MAX(0, D18-C18)*VERI_TABANI!$B$8 | I18: =D18*(VERI_TABANI!$B$13-VERI_TABANI!$B$14)*VERI_TABANI!G24 | J18: =H18+I18 | K18: =IFERROR((D18*VERI_TABANI!$B$14)/(D18*VERI_TABANI!$B$13), 0) | L18: =IFERROR(G18/(H18/VERI_TABANI!B24), 0) | M18: =IFERROR(G18/(I18/VERI_TABANI!B24), 0) | N18: =IFERROR(G18/(J18/VERI_TABANI!B24), 0) | O18: =C18*DASHBOARD!$B$7 | P18: =(O18/VERI_TABANI!B24)/VERI_TABANI!$B$4 | Q18: =MAX(0, P18-P17) | R18: =Q18*VERI_TABANI!$B$6 | S18: =MIN(MAX(0, C18-D18), O18)*VERI_TABANI!$B$7 + MAX(0, O18-MAX(0, C18-D18))*VERI_TABANI!$B$8 | T18: =O18*(VERI_TABANI!$B$13-VERI_TABANI!$B$15)*VERI_TABANI!G24 | U18: =S18+T18 | V18: =IFERROR((O18*VERI_TABANI!$B$15)/(O18*VERI_TABANI!$B$13), 0) | W18: =IFERROR(R18/(S18/VERI_TABANI!B24), 0) | X18: =IFERROR(R18/(T18/VERI_TABANI!B24), 0) | Y18: =IFERROR(R18/(U18/VERI_TABANI!B24), 0) | Z18: =IF(ABS(DASHBOARD!$B$8)=1, VERI_TABANI!E24*(1-0.928), 0) | AA18: =IF(ABS(DASHBOARD!$B$8)=1, VERI_TABANI!F24, 0) | AB18: =AA18/VERI_TABANI!B24 | AC18: =IF(DASHBOARD!$B$8=1, MAX(0, AB18-AB17)*(VERI_TABANI!$B$10+VERI_TABANI!$B$12), IF(DASHBOARD!$B$8=-1, MAX(0, AB18-AB17)*(VERI_TABANI!$B$11+VERI_TABANI!$B$12), 0)) | AD18: =Z18*VERI_TABANI!$B$9 | AE18: =Z18*0.00206091519919798*VERI_TABANI!G24 | AF18: =AD18+AE18 | AG18: =IFERROR((IF($B$8=1, AA18*VERI_TABANI!B16, IF($B$8=-1, AA18*VERI_TABANI!B17, 0))) / (Z18*VERI_TABANI!B18), 0) | AH18: =IFERROR(AC18/(AD18/VERI_TABANI!B24), 0) | AI18: =IFERROR(AC18/(AE18/VERI_TABANI!B24), 0) | AJ18: =IFERROR(AC18/(AF18/VERI_TABANI!B24), 0) | AK18: =G18 | AL18: =R18 | AM18: =AC18 | AN18: =AK18+AL18+AM18 | AO18: =D18*(VERI_TABANI!$B$13-VERI_TABANI!$B$14) | AP18: =O18*(VERI_TABANI!$B$13-VERI_TABANI!$B$15) | AQ18: =IF($B$8=1, AA18*(0.00202-VERI_TABANI!B16), IF($B$8=-1, AA18*(0.00202-VERI_TABANI!B17), 0)) | AR18: =AO18+AP18+AQ18 | AS18: =I18+T18+AE18 | AT18: =IFERROR((D18*VERI_TABANI!$B$14 + O18*VERI_TABANI!$B$15 + IF($B$8=1, AA18*VERI_TABANI!B16, IF($B$8=-1, AA18*VERI_TABANI!B17, 0))) / ((D18+O18)*VERI_TABANI!$B$13 + Z18*VERI_TABANI!B18), 0) | AU18: =J18 | AV18: =U18 | AW18: =AF18 | AX18: =AU18+AV18+AW18 | AY18: =IFERROR(AN18/((H18+S18+AD18)/VERI_TABANI!B23), 0) | AZ18: =IFERROR(AN18/((I18+T18+AE18)/VERI_TABANI!B23), 0) | BA18: =IFERROR(AN18/(AX18/VERI_TABANI!B24), 0)
A19: =VERI_TABANI!A25 | B19: =VERI_TABANI!C25 | C19: =VERI_TABANI!D25 | D19: =C19*DASHBOARD!$B$6 | E19: =(D19/VERI_TABANI!B25)/VERI_TABANI!$B$3 | F19: =MAX(0, E19-E18) | G19: =F19*VERI_TABANI!$B$5 | H19: =MIN(C19, D19)*VERI_TABANI!$B$7 + MAX(0, D19-C19)*VERI_TABANI!$B$8 | I19: =D19*(VERI_TABANI!$B$13-VERI_TABANI!$B$14)*VERI_TABANI!G25 | J19: =H19+I19 | K19: =IFERROR((D19*VERI_TABANI!$B$14)/(D19*VERI_TABANI!$B$13), 0) | L19: =IFERROR(G19/(H19/VERI_TABANI!B25), 0) | M19: =IFERROR(G19/(I19/VERI_TABANI!B25), 0) | N19: =IFERROR(G19/(J19/VERI_TABANI!B25), 0) | O19: =C19*DASHBOARD!$B$7 | P19: =(O19/VERI_TABANI!B25)/VERI_TABANI!$B$4 | Q19: =MAX(0, P19-P18) | R19: =Q19*VERI_TABANI!$B$6 | S19: =MIN(MAX(0, C19-D19), O19)*VERI_TABANI!$B$7 + MAX(0, O19-MAX(0, C19-D19))*VERI_TABANI!$B$8 | T19: =O19*(VERI_TABANI!$B$13-VERI_TABANI!$B$15)*VERI_TABANI!G25 | U19: =S19+T19 | V19: =IFERROR((O19*VERI_TABANI!$B$15)/(O19*VERI_TABANI!$B$13), 0) | W19: =IFERROR(R19/(S19/VERI_TABANI!B25), 0) | X19: =IFERROR(R19/(T19/VERI_TABANI!B25), 0) | Y19: =IFERROR(R19/(U19/VERI_TABANI!B25), 0) | Z19: =IF(ABS(DASHBOARD!$B$8)=1, VERI_TABANI!E25*(1-0.928), 0) | AA19: =IF(ABS(DASHBOARD!$B$8)=1, VERI_TABANI!F25, 0) | AB19: =AA19/VERI_TABANI!B25 | AC19: =IF(DASHBOARD!$B$8=1, MAX(0, AB19-AB18)*(VERI_TABANI!$B$10+VERI_TABANI!$B$12), IF(DASHBOARD!$B$8=-1, MAX(0, AB19-AB18)*(VERI_TABANI!$B$11+VERI_TABANI!$B$12), 0)) | AD19: =Z19*VERI_TABANI!$B$9 | AE19: =Z19*0.00206091519919798*VERI_TABANI!G25 | AF19: =AD19+AE19 | AG19: =IFERROR((IF($B$8=1, AA19*VERI_TABANI!B16, IF($B$8=-1, AA19*VERI_TABANI!B17, 0))) / (Z19*VERI_TABANI!B18), 0) | AH19: =IFERROR(AC19/(AD19/VERI_TABANI!B25), 0) | AI19: =IFERROR(AC19/(AE19/VERI_TABANI!B25), 0) | AJ19: =IFERROR(AC19/(AF19/VERI_TABANI!B25), 0) | AK19: =G19 | AL19: =R19 | AM19: =AC19 | AN19: =AK19+AL19+AM19 | AO19: =D19*(VERI_TABANI!$B$13-VERI_TABANI!$B$14) | AP19: =O19*(VERI_TABANI!$B$13-VERI_TABANI!$B$15) | AQ19: =IF($B$8=1, AA19*(0.00202-VERI_TABANI!B16), IF($B$8=-1, AA19*(0.00202-VERI_TABANI!B17), 0)) | AR19: =AO19+AP19+AQ19 | AS19: =I19+T19+AE19 | AT19: =IFERROR((D19*VERI_TABANI!$B$14 + O19*VERI_TABANI!$B$15 + IF($B$8=1, AA19*VERI_TABANI!B16, IF($B$8=-1, AA19*VERI_TABANI!B17, 0))) / ((D19+O19)*VERI_TABANI!$B$13 + Z19*VERI_TABANI!B18), 0) | AU19: =J19 | AV19: =U19 | AW19: =AF19 | AX19: =AU19+AV19+AW19 | AY19: =IFERROR(AN19/((H19+S19+AD19)/VERI_TABANI!B23), 0) | AZ19: =IFERROR(AN19/((I19+T19+AE19)/VERI_TABANI!B23), 0) | BA19: =IFERROR(AN19/(AX19/VERI_TABANI!B25), 0)
A20: =VERI_TABANI!A26 | B20: =VERI_TABANI!C26 | C20: =VERI_TABANI!D26 | D20: =C20*DASHBOARD!$B$6 | E20: =(D20/VERI_TABANI!B26)/VERI_TABANI!$B$3 | F20: =MAX(0, E20-E19) | G20: =F20*VERI_TABANI!$B$5 | H20: =MIN(C20, D20)*VERI_TABANI!$B$7 + MAX(0, D20-C20)*VERI_TABANI!$B$8 | I20: =D20*(VERI_TABANI!$B$13-VERI_TABANI!$B$14)*VERI_TABANI!G26 | J20: =H20+I20 | K20: =IFERROR((D20*VERI_TABANI!$B$14)/(D20*VERI_TABANI!$B$13), 0) | L20: =IFERROR(G20/(H20/VERI_TABANI!B26), 0) | M20: =IFERROR(G20/(I20/VERI_TABANI!B26), 0) | N20: =IFERROR(G20/(J20/VERI_TABANI!B26), 0) | O20: =C20*DASHBOARD!$B$7 | P20: =(O20/VERI_TABANI!B26)/VERI_TABANI!$B$4 | Q20: =MAX(0, P20-P19) | R20: =Q20*VERI_TABANI!$B$6 | S20: =MIN(MAX(0, C20-D20), O20)*VERI_TABANI!$B$7 + MAX(0, O20-MAX(0, C20-D20))*VERI_TABANI!$B$8 | T20: =O20*(VERI_TABANI!$B$13-VERI_TABANI!$B$15)*VERI_TABANI!G26 | U20: =S20+T20 | V20: =IFERROR((O20*VERI_TABANI!$B$15)/(O20*VERI_TABANI!$B$13), 0) | W20: =IFERROR(R20/(S20/VERI_TABANI!B26), 0) | X20: =IFERROR(R20/(T20/VERI_TABANI!B26), 0) | Y20: =IFERROR(R20/(U20/VERI_TABANI!B26), 0) | Z20: =IF(ABS(DASHBOARD!$B$8)=1, VERI_TABANI!E26*(1-0.928), 0) | AA20: =IF(ABS(DASHBOARD!$B$8)=1, VERI_TABANI!F26, 0) | AB20: =AA20/VERI_TABANI!B26 | AC20: =IF(DASHBOARD!$B$8=1, MAX(0, AB20-AB19)*(VERI_TABANI!$B$10+VERI_TABANI!$B$12), IF(DASHBOARD!$B$8=-1, MAX(0, AB20-AB19)*(VERI_TABANI!$B$11+VERI_TABANI!$B$12), 0)) | AD20: =Z20*VERI_TABANI!$B$9 | AE20: =Z20*0.00206091519919798*VERI_TABANI!G26 | AF20: =AD20+AE20 | AG20: =IFERROR((IF($B$8=1, AA20*VERI_TABANI!B16, IF($B$8=-1, AA20*VERI_TABANI!B17, 0))) / (Z20*VERI_TABANI!B18), 0) | AH20: =IFERROR(AC20/(AD20/VERI_TABANI!B26), 0) | AI20: =IFERROR(AC20/(AE20/VERI_TABANI!B26), 0) | AJ20: =IFERROR(AC20/(AF20/VERI_TABANI!B26), 0) | AK20: =G20 | AL20: =R20 | AM20: =AC20 | AN20: =AK20+AL20+AM20 | AO20: =D20*(VERI_TABANI!$B$13-VERI_TABANI!$B$14) | AP20: =O20*(VERI_TABANI!$B$13-VERI_TABANI!$B$15) | AQ20: =IF($B$8=1, AA20*(0.00202-VERI_TABANI!B16), IF($B$8=-1, AA20*(0.00202-VERI_TABANI!B17), 0)) | AR20: =AO20+AP20+AQ20 | AS20: =I20+T20+AE20 | AT20: =IFERROR((D20*VERI_TABANI!$B$14 + O20*VERI_TABANI!$B$15 + IF($B$8=1, AA20*VERI_TABANI!B16, IF($B$8=-1, AA20*VERI_TABANI!B17, 0))) / ((D20+O20)*VERI_TABANI!$B$13 + Z20*VERI_TABANI!B18), 0) | AU20: =J20 | AV20: =U20 | AW20: =AF20 | AX20: =AU20+AV20+AW20 | AY20: =IFERROR(AN20/((H20+S20+AD20)/VERI_TABANI!B23), 0) | AZ20: =IFERROR(AN20/((I20+T20+AE20)/VERI_TABANI!B23), 0) | BA20: =IFERROR(AN20/(AX20/VERI_TABANI!B26), 0)
A21: =VERI_TABANI!A27 | B21: =VERI_TABANI!C27 | C21: =VERI_TABANI!D27 | D21: =C21*DASHBOARD!$B$6 | E21: =(D21/VERI_TABANI!B27)/VERI_TABANI!$B$3 | F21: =MAX(0, E21-E20) | G21: =F21*VERI_TABANI!$B$5 | H21: =MIN(C21, D21)*VERI_TABANI!$B$7 + MAX(0, D21-C21)*VERI_TABANI!$B$8 | I21: =D21*(VERI_TABANI!$B$13-VERI_TABANI!$B$14)*VERI_TABANI!G27 | J21: =H21+I21 | K21: =IFERROR((D21*VERI_TABANI!$B$14)/(D21*VERI_TABANI!$B$13), 0) | L21: =IFERROR(G21/(H21/VERI_TABANI!B27), 0) | M21: =IFERROR(G21/(I21/VERI_TABANI!B27), 0) | N21: =IFERROR(G21/(J21/VERI_TABANI!B27), 0) | O21: =C21*DASHBOARD!$B$7 | P21: =(O21/VERI_TABANI!B27)/VERI_TABANI!$B$4 | Q21: =MAX(0, P21-P20) | R21: =Q21*VERI_TABANI!$B$6 | S21: =MIN(MAX(0, C21-D21), O21)*VERI_TABANI!$B$7 + MAX(0, O21-MAX(0, C21-D21))*VERI_TABANI!$B$8 | T21: =O21*(VERI_TABANI!$B$13-VERI_TABANI!$B$15)*VERI_TABANI!G27 | U21: =S21+T21 | V21: =IFERROR((O21*VERI_TABANI!$B$15)/(O21*VERI_TABANI!$B$13), 0) | W21: =IFERROR(R21/(S21/VERI_TABANI!B27), 0) | X21: =IFERROR(R21/(T21/VERI_TABANI!B27), 0) | Y21: =IFERROR(R21/(U21/VERI_TABANI!B27), 0) | Z21: =IF(ABS(DASHBOARD!$B$8)=1, VERI_TABANI!E27*(1-0.928), 0) | AA21: =IF(ABS(DASHBOARD!$B$8)=1, VERI_TABANI!F27, 0) | AB21: =AA21/VERI_TABANI!B27 | AC21: =IF(DASHBOARD!$B$8=1, MAX(0, AB21-AB20)*(VERI_TABANI!$B$10+VERI_TABANI!$B$12), IF(DASHBOARD!$B$8=-1, MAX(0, AB21-AB20)*(VERI_TABANI!$B$11+VERI_TABANI!$B$12), 0)) | AD21: =Z21*VERI_TABANI!$B$9 | AE21: =Z21*0.00206091519919798*VERI_TABANI!G27 | AF21: =AD21+AE21 | AG21: =IFERROR((IF($B$8=1, AA21*VERI_TABANI!B16, IF($B$8=-1, AA21*VERI_TABANI!B17, 0))) / (Z21*VERI_TABANI!B18), 0) | AH21: =IFERROR(AC21/(AD21/VERI_TABANI!B27), 0) | AI21: =IFERROR(AC21/(AE21/VERI_TABANI!B27), 0) | AJ21: =IFERROR(AC21/(AF21/VERI_TABANI!B27), 0) | AK21: =G21 | AL21: =R21 | AM21: =AC21 | AN21: =AK21+AL21+AM21 | AO21: =D21*(VERI_TABANI!$B$13-VERI_TABANI!$B$14) | AP21: =O21*(VERI_TABANI!$B$13-VERI_TABANI!$B$15) | AQ21: =IF($B$8=1, AA21*(0.00202-VERI_TABANI!B16), IF($B$8=-1, AA21*(0.00202-VERI_TABANI!B17), 0)) | AR21: =AO21+AP21+AQ21 | AS21: =I21+T21+AE21 | AT21: =IFERROR((D21*VERI_TABANI!$B$14 + O21*VERI_TABANI!$B$15 + IF($B$8=1, AA21*VERI_TABANI!B16, IF($B$8=-1, AA21*VERI_TABANI!B17, 0))) / ((D21+O21)*VERI_TABANI!$B$13 + Z21*VERI_TABANI!B18), 0) | AU21: =J21 | AV21: =U21 | AW21: =AF21 | AX21: =AU21+AV21+AW21 | AY21: =IFERROR(AN21/((H21+S21+AD21)/VERI_TABANI!B23), 0) | AZ21: =IFERROR(AN21/((I21+T21+AE21)/VERI_TABANI!B23), 0) | BA21: =IFERROR(AN21/(AX21/VERI_TABANI!B27), 0)
A22: =VERI_TABANI!A28 | B22: =VERI_TABANI!C28 | C22: =VERI_TABANI!D28 | D22: =C22*DASHBOARD!$B$6 | E22: =(D22/VERI_TABANI!B28)/VERI_TABANI!$B$3 | F22: =MAX(0, E22-E21) | G22: =F22*VERI_TABANI!$B$5 | H22: =MIN(C22, D22)*VERI_TABANI!$B$7 + MAX(0, D22-C22)*VERI_TABANI!$B$8 | I22: =D22*(VERI_TABANI!$B$13-VERI_TABANI!$B$14)*VERI_TABANI!G28 | J22: =H22+I22 | K22: =IFERROR((D22*VERI_TABANI!$B$14)/(D22*VERI_TABANI!$B$13), 0) | L22: =IFERROR(G22/(H22/VERI_TABANI!B28), 0) | M22: =IFERROR(G22/(I22/VERI_TABANI!B28), 0) | N22: =IFERROR(G22/(J22/VERI_TABANI!B28), 0) | O22: =C22*DASHBOARD!$B$7 | P22: =(O22/VERI_TABANI!B28)/VERI_TABANI!$B$4 | Q22: =MAX(0, P22-P21) | R22: =Q22*VERI_TABANI!$B$6 | S22: =MIN(MAX(0, C22-D22), O22)*VERI_TABANI!$B$7 + MAX(0, O22-MAX(0, C22-D22))*VERI_TABANI!$B$8 | T22: =O22*(VERI_TABANI!$B$13-VERI_TABANI!$B$15)*VERI_TABANI!G28 | U22: =S22+T22 | V22: =IFERROR((O22*VERI_TABANI!$B$15)/(O22*VERI_TABANI!$B$13), 0) | W22: =IFERROR(R22/(S22/VERI_TABANI!B28), 0) | X22: =IFERROR(R22/(T22/VERI_TABANI!B28), 0) | Y22: =IFERROR(R22/(U22/VERI_TABANI!B28), 0) | Z22: =IF(ABS(DASHBOARD!$B$8)=1, VERI_TABANI!E28*(1-0.928), 0) | AA22: =IF(ABS(DASHBOARD!$B$8)=1, VERI_TABANI!F28, 0) | AB22: =AA22/VERI_TABANI!B28 | AC22: =IF(DASHBOARD!$B$8=1, MAX(0, AB22-AB21)*(VERI_TABANI!$B$10+VERI_TABANI!$B$12), IF(DASHBOARD!$B$8=-1, MAX(0, AB22-AB21)*(VERI_TABANI!$B$11+VERI_TABANI!$B$12), 0)) | AD22: =Z22*VERI_TABANI!$B$9 | AE22: =Z22*0.00206091519919798*VERI_TABANI!G28 | AF22: =AD22+AE22 | AG22: =IFERROR((IF($B$8=1, AA22*VERI_TABANI!B16, IF($B$8=-1, AA22*VERI_TABANI!B17, 0))) / (Z22*VERI_TABANI!B18), 0) | AH22: =IFERROR(AC22/(AD22/VERI_TABANI!B28), 0) | AI22: =IFERROR(AC22/(AE22/VERI_TABANI!B28), 0) | AJ22: =IFERROR(AC22/(AF22/VERI_TABANI!B28), 0) | AK22: =G22 | AL22: =R22 | AM22: =AC22 | AN22: =AK22+AL22+AM22 | AO22: =D22*(VERI_TABANI!$B$13-VERI_TABANI!$B$14) | AP22: =O22*(VERI_TABANI!$B$13-VERI_TABANI!$B$15) | AQ22: =IF($B$8=1, AA22*(0.00202-VERI_TABANI!B16), IF($B$8=-1, AA22*(0.00202-VERI_TABANI!B17), 0)) | AR22: =AO22+AP22+AQ22 | AS22: =I22+T22+AE22 | AT22: =IFERROR((D22*VERI_TABANI!$B$14 + O22*VERI_TABANI!$B$15 + IF($B$8=1, AA22*VERI_TABANI!B16, IF($B$8=-1, AA22*VERI_TABANI!B17, 0))) / ((D22+O22)*VERI_TABANI!$B$13 + Z22*VERI_TABANI!B18), 0) | AU22: =J22 | AV22: =U22 | AW22: =AF22 | AX22: =AU22+AV22+AW22 | AY22: =IFERROR(AN22/((H22+S22+AD22)/VERI_TABANI!B23), 0) | AZ22: =IFERROR(AN22/((I22+T22+AE22)/VERI_TABANI!B23), 0) | BA22: =IFERROR(AN22/(AX22/VERI_TABANI!B28), 0)
A23: GENEL TOPLAM | B23: =SUM(B17:B22) | C23: =SUM(C17:C22) | D23: =SUM(D17:D22) | E23: =MAX(E17:E22) | F23: =SUM(F17:F22) | G23: =SUM(G17:G22) | H23: =SUM(H17:H22) | I23: =SUM(I17:I22) | J23: =SUM(J17:J22) | K23: =IFERROR((D23*VERI_TABANI!$B$14)/(D23*VERI_TABANI!$B$13), 0) | L23: =IFERROR(G23/(H23/29), 0) | M23: =IFERROR(G23/(I23/29), 0) | N23: =IFERROR(G23/(J23/29), 0) | O23: =SUM(O17:O22) | P23: =MAX(P17:P22) | Q23: =SUM(Q17:Q22) | R23: =SUM(R17:R22) | S23: =SUM(S17:S22) | T23: =SUM(T17:T22) | U23: =SUM(U17:U22) | V23: =IFERROR((O23*VERI_TABANI!$B$15)/(O23*VERI_TABANI!$B$13), 0) | W23: =IFERROR(R23/(S23/29), 0) | X23: =IFERROR(R23/(T23/29), 0) | Y23: =IFERROR(R23/(U23/29), 0) | Z23: =SUM(Z17:Z22) | AA23: =SUM(AA17:AA22) | AB23: =MAX(AB17:AB22) | AC23: =SUM(AC17:AC22) | AD23: =SUM(AD17:AD22) | AE23: =SUM(AE17:AE22) | AF23: =SUM(AF17:AF22) | AG23: =IFERROR((IF($B$8=1, AA23*VERI_TABANI!B16, IF($B$8=-1, AA23*VERI_TABANI!B17, 0))) / (Z23*VERI_TABANI!B18), 0) | AH23: =IFERROR(AC23/(AD23/29), 0) | AI23: =IFERROR(AC23/(AE23/29), 0) | AJ23: =IFERROR(AC23/(AF23/29), 0) | AK23: =SUM(AK17:AK22) | AL23: =SUM(AL17:AL22) | AM23: =SUM(AM17:AM22) | AN23: =SUM(AN17:AN22) | AO23: =SUM(AO17:AO22) | AP23: =SUM(AP17:AP22) | AQ23: =SUM(AQ17:AQ22) | AR23: =SUM(AR17:AR22) | AS23: =SUM(AS17:AS22) | AT23: =IFERROR((D23*VERI_TABANI!$B$14 + O23*VERI_TABANI!$B$15 + IF($B$8=1, AA23*VERI_TABANI!B16, IF($B$8=-1, AA23*VERI_TABANI!B17, 0))) / ((D23+O23)*VERI_TABANI!$B$13 + Z23*VERI_TABANI!B18), 0) | AU23: =SUM(AU17:AU22) | AV23: =SUM(AV17:AV22) | AW23: =SUM(AW17:AW22) | AX23: =SUM(AX17:AX22) | AY23: =IFERROR(AN23/((H23+S23+AD23)/29), 0) | AZ23: =IFERROR(AN23/((I23+T23+AE23)/29), 0) | BA23: =IFERROR(AN23/(AX23/29), 0)

Sheet SUREKLI_SENARYO_MATRISI
A1: 441 KOMBİNASYONLU TAM DUYARLILIK SİMÜLASYON MATRİSİ (GES %0-%200, RES %0-%200, H2 %0-%20)
A4: Senaryo No | B4: GES Oranı (%) | C4: RES Oranı (%) | D4: H2 Durumu | E4: EPDK Rejimi | F4: Kümülatif Yatırım (€) | G4: 29 Yıllık Net Fayda (€) | H4: Engellenen Net Karbon (tCO2) | I4: Birleşik LCA Oranı (%) | J4: Basit Amortisman Süresi (Yıl) | K4: Karbon/CAPEX (tCO2/€) | L4: LCA Footprint | M4: Net Metering Distance | N4: ROI Ratio | O4: Scope 1+2 Shield Helper | P4: Knee Point Distance | Q4: Wind-Solar Sinerji Match | R4: Payback Sort Helper | S4: Filtered Net Fayda | T4: Filtered Payback | U4: Filtered ROI | V4: Filtered Carbon | W4: Filtered CO2/CAPEX | X4: Filtered EPDK Match | Y4: Filtered LCA % | Z4: Filtered Scope 1+2 | AA4: Filtered Knee Point | AB4: Filtered Synergy
A5: 1 | B5: 0 | C5: 0 | D5: Yok (%0) | E5: =IF((B5+C5)<=1, "Tam Mahsuplaşma (≤%100)", "Kısmi Satış (>%100)") | F5: =((VERI_TABANI!$D$29*B5/VERI_TABANI!$B$29)/VERI_TABANI!$B$3)*VERI_TABANI!$B$5 + ((VERI_TABANI!$D$29*C5/VERI_TABANI!$B$29)/VERI_TABANI!$B$4)*VERI_TABANI!$B$6 + IF(ISNUMBER(SEARCH("Var", D5)), (VERI_TABANI!$F$29/VERI_TABANI!$B$29)*(VERI_TABANI!$B$10+VERI_TABANI!$B$12), 0) | G5: =(((MIN(VERI_TABANI!D23, VERI_TABANI!D23*B5)*VERI_TABANI!$B$7 + MAX(0, VERI_TABANI!D23*B5-VERI_TABANI!D23)*VERI_TABANI!$B$8) + (MIN(MAX(0, VERI_TABANI!D23-VERI_TABANI!D23*B5), VERI_TABANI!D23*C5)*VERI_TABANI!$B$7 + MAX(0, VERI_TABANI!D23*C5-MAX(0, VERI_TABANI!D23-VERI_TABANI!D23*B5))*VERI_TABANI!$B$8) + IF(ABS(IF(ISNUMBER(SEARCH("Var", D5)), 1, IF(ISNUMBER(SEARCH("Gri", D5)), -1, 0)))=1, VERI_TABANI!E23*(1-0.928)*VERI_TABANI!$B$9, 0) + (VERI_TABANI!D23*B5*(VERI_TABANI!$B$13-VERI_TABANI!$B$14)*VERI_TABANI!G23) + (VERI_TABANI!D23*C5*(VERI_TABANI!$B$13-VERI_TABANI!$B$15)*VERI_TABANI!G23) + IF(ABS(IF(ISNUMBER(SEARCH("Var", D5)), 1, IF(ISNUMBER(SEARCH("Gri", D5)), -1, 0)))=1, VERI_TABANI!E23*(1-0.928)*0.00206091519919798*VERI_TABANI!G23, 0)) + ((MIN(VERI_TABANI!D24, VERI_TABANI!D24*B5)*VERI_TABANI!$B$7 + MAX(0, VERI_TABANI!D24*B5-VERI_TABANI!D24)*VERI_TABANI!$B$8) + (MIN(MAX(0, VERI_TABANI!D24-VERI_TABANI!D24*B5), VERI_TABANI!D24*C5)*VERI_TABANI!$B$7 + MAX(0, VERI_TABANI!D24*C5-MAX(0, VERI_TABANI!D24-VERI_TABANI!D24*B5))*VERI_TABANI!$B$8) + IF(ABS(IF(ISNUMBER(SEARCH("Var", D5)), 1, IF(ISNUMBER(SEARCH("Gri", D5)), -1, 0)))=1, VERI_TABANI!E24*(1-0.928)*VERI_TABANI!$B$9, 0) + (VERI_TABANI!D24*B5*(VERI_TABANI!$B$13-VERI_TABANI!$B$14)*VERI_TABANI!G24) + (VERI_TABANI!D24*C5*(VERI_TABANI!$B$13-VERI_TABANI!$B$15)*VERI_TABANI!G24) + IF(ABS(IF(ISNUMBER(SEARCH("Var", D5)), 1, IF(ISNUMBER(SEARCH("Gri", D5)), -1, 0)))=1, VERI_TABANI!E24*(1-0.928)*0.00206091519919798*VERI_TABANI!G24, 0)) + ((MIN(VERI_TABANI!D25, VERI_TABANI!D25*B5)*VERI_TABANI!$B$7 + MAX(0, VERI_TABANI!D25*B5-VERI_TABANI!D25)*VERI_TABANI!$B$8) + (MIN(MAX(0, VERI_TABANI!D25-VERI_TABANI!D25*B5), VERI_TABANI!D25*C5)*VERI_TABANI!$B$7 + MAX(0, VERI_TABANI!D25*C5-MAX(0, VERI_TABANI!D25-VERI_TABANI!D25*B5))*VERI_TABANI!$B$8) + IF(ABS(IF(ISNUMBER(SEARCH("Var", D5)), 1, IF(ISNUMBER(SEARCH("Gri", D5)), -1, 0)))=1, VERI_TABANI!E25*(1-0.928)*VERI_TABANI!$B$9, 0) + (VERI_TABANI!D25*B5*(VERI_TABANI!$B$13-VERI_TABANI!$B$14)*VERI_TABANI!G25) + (VERI_TABANI!D25*C5*(VERI_TABANI!$B$13-VERI_TABANI!$B$15)*VERI_TABANI!G25) + IF(ABS(IF(ISNUMBER(SEARCH("Var", D5)), 1, IF(ISNUMBER(SEARCH("Gri", D5)), -1, 0)))=1, VERI_TABANI!E25*(1-0.928)*0.00206091519919798*VERI_TABANI!G25, 0)) + ((MIN(VERI_TABANI!D26, VERI_TABANI!D26*B5)*VERI_TABANI!$B$7 + MAX(0, VERI_TABANI!D26*B5-VERI_TABANI!D26)*VERI_TABANI!$B$8) + (MIN(MAX(0, VERI_TABANI!D26-VERI_TABANI!D26*B5), VERI_TABANI!D26*C5)*VERI_TABANI!$B$7 + MAX(0, VERI_TABANI!D26*C5-MAX(0, VERI_TABANI!D26-VERI_TABANI!D26*B5))*VERI_TABANI!$B$8) + IF(ABS(IF(ISNUMBER(SEARCH("Var", D5)), 1, IF(ISNUMBER(SEARCH("Gri", D5)), -1, 0)))=1, VERI_TABANI!E26*(1-0.928)*VERI_TABANI!$B$9, 0) + (VERI_TABANI!D26*B5*(VERI_TABANI!$B$13-VERI_TABANI!$B$14)*VERI_TABANI!G26) + (VERI_TABANI!D26*C5*(VERI_TABANI!$B$13-VERI_TABANI!$B$15)*VERI_TABANI!G26) + IF(ABS(IF(ISNUMBER(SEARCH("Var", D5)), 1, IF(ISNUMBER(SEARCH("Gri", D5)), -1, 0)))=1, VERI_TABANI!E26*(1-0.928)*0.00206091519919798*VERI_TABANI!G26, 0)) + ((MIN(VERI_TABANI!D27, VERI_TABANI!D27*B5)*VERI_TABANI!$B$7 + MAX(0, VERI_TABANI!D27*B5-VERI_TABANI!D27)*VERI_TABANI!$B$8) + (MIN(MAX(0, VERI_TABANI!D27-VERI_TABANI!D27*B5), VERI_TABANI!D27*C5)*VERI_TABANI!$B$7 + MAX(0, VERI_TABANI!D27*C5-MAX(0, VERI_TABANI!D27-VERI_TABANI!D27*B5))*VERI_TABANI!$B$8) + IF(ABS(IF(ISNUMBER(SEARCH("Var", D5)), 1, IF(ISNUMBER(SEARCH("Gri", D5)), -1, 0)))=1, VERI_TABANI!E27*(1-0.928)*VERI_TABANI!$B$9, 0) + (VERI_TABANI!D27*B5*(VERI_TABANI!$B$13-VERI_TABANI!$B$14)*VERI_TABANI!G27) + (VERI_TABANI!D27*C5*(VERI_TABANI!$B$13-VERI_TABANI!$B$15)*VERI_TABANI!G27) + IF(ABS(IF(ISNUMBER(SEARCH("Var", D5)), 1, IF(ISNUMBER(SEARCH("Gri", D5)), -1, 0)))=1, VERI_TABANI!E27*(1-0.928)*0.00206091519919798*VERI_TABANI!G27, 0)) + ((MIN(VERI_TABANI!D28, VERI_TABANI!D28*B5)*VERI_TABANI!$B$7 + MAX(0, VERI_TABANI!D28*B5-VERI_TABANI!D28)*VERI_TABANI!$B$8) + (MIN(MAX(0, VERI_TABANI!D28-VERI_TABANI!D28*B5), VERI_TABANI!D28*C5)*VERI_TABANI!$B$7 + MAX(0, VERI_TABANI!D28*C5-MAX(0, VERI_TABANI!D28-VERI_TABANI!D28*B5))*VERI_TABANI!$B$8) + IF(ABS(IF(ISNUMBER(SEARCH("Var", D5)), 1, IF(ISNUMBER(SEARCH("Gri", D5)), -1, 0)))=1, VERI_TABANI!E28*(1-0.928)*VERI_TABANI!$B$9, 0) + (VERI_TABANI!D28*B5*(VERI_TABANI!$B$13-VERI_TABANI!$B$14)*VERI_TABANI!G28) + (VERI_TABANI!D28*C5*(VERI_TABANI!$B$13-VERI_TABANI!$B$15)*VERI_TABANI!G28) + IF(ABS(IF(ISNUMBER(SEARCH("Var", D5)), 1, IF(ISNUMBER(SEARCH("Gri", D5)), -1, 0)))=1, VERI_TABANI!E28*(1-0.928)*0.00206091519919798*VERI_TABANI!G28, 0))) | H5: =(((VERI_TABANI!D23*B5*(VERI_TABANI!$B$13-VERI_TABANI!$B$14)) + (VERI_TABANI!D23*C5*(VERI_TABANI!$B$13-VERI_TABANI!$B$15)) + IF(ISNUMBER(SEARCH("Var", D5)), VERI_TABANI!F23*(0.00202-VERI_TABANI!$B$16), IF(ISNUMBER(SEARCH("Gri", D5)), VERI_TABANI!F23*(0.00202-VERI_TABANI!$B$17), 0))) + ((VERI_TABANI!D24*B5*(VERI_TABANI!$B$13-VERI_TABANI!$B$14)) + (VERI_TABANI!D24*C5*(VERI_TABANI!$B$13-VERI_TABANI!$B$15)) + IF(ISNUMBER(SEARCH("Var", D5)), VERI_TABANI!F24*(0.00202-VERI_TABANI!$B$16), IF(ISNUMBER(SEARCH("Gri", D5)), VERI_TABANI!F24*(0.00202-VERI_TABANI!$B$17), 0))) + ((VERI_TABANI!D25*B5*(VERI_TABANI!$B$13-VERI_TABANI!$B$14)) + (VERI_TABANI!D25*C5*(VERI_TABANI!$B$13-VERI_TABANI!$B$15)) + IF(ISNUMBER(SEARCH("Var", D5)), VERI_TABANI!F25*(0.00202-VERI_TABANI!$B$16), IF(ISNUMBER(SEARCH("Gri", D5)), VERI_TABANI!F25*(0.00202-VERI_TABANI!$B$17), 0))) + ((VERI_TABANI!D26*B5*(VERI_TABANI!$B$13-VERI_TABANI!$B$14)) + (VERI_TABANI!D26*C5*(VERI_TABANI!$B$13-VERI_TABANI!$B$15)) + IF(ISNUMBER(SEARCH("Var", D5)), VERI_TABANI!F26*(0.00202-VERI_TABANI!$B$16), IF(ISNUMBER(SEARCH("Gri", D5)), VERI_TABANI!F26*(0.00202-VERI_TABANI!$B$17), 0))) + ((VERI_TABANI!D27*B5*(VERI_TABANI!$B$13-VERI_TABANI!$B$14)) + (VERI_TABANI!D27*C5*(VERI_TABANI!$B$13-VERI_TABANI!$B$15)) + IF(ISNUMBER(SEARCH("Var", D5)), VERI_TABANI!F27*(0.00202-VERI_TABANI!$B$16), IF(ISNUMBER(SEARCH("Gri", D5)), VERI_TABANI!F27*(0.00202-VERI_TABANI!$B$17), 0))) + ((VERI_TABANI!D28*B5*(VERI_TABANI!$B$13-VERI_TABANI!$B$14)) + (VERI_TABANI!D28*C5*(VERI_TABANI!$B$13-VERI_TABANI!$B$15)) + IF(ISNUMBER(SEARCH("Var", D5)), VERI_TABANI!F28*(0.00202-VERI_TABANI!$B$16), IF(ISNUMBER(SEARCH("Gri", D5)), VERI_TABANI!F28*(0.00202-VERI_TABANI!$B$17), 0)))) | I5: =IFERROR(((VERI_TABANI!$D$29*B5*VERI_TABANI!$B$14 + VERI_TABANI!$D$29*C5*VERI_TABANI!$B$15 + IF(ISNUMBER(SEARCH("Var", D5)), VERI_TABANI!$F$29*VERI_TABANI!$B$16, 0))) / (((VERI_TABANI!$D$29*B5 + VERI_TABANI!$D$29*C5)*VERI_TABANI!$B$13 + IF(ISNUMBER(SEARCH("Var", D5)), VERI_TABANI!$E$29*(1-0.928)*VERI_TABANI!$B$18, 0))), 0) | J5: =IFERROR(F5/(G5/29), 0) | K5: =IF(F5>0, H5/F5, 0) | L5: =IF(F5>0, I5, 1000000000) | M5: =ABS((B5+C5)-1) | N5: =IF(F5>0, (G5/29)/F5, 0) | O5: =IF(AND((B5+C5)>=1, ISNUMBER(SEARCH("Var", D5))), F5, 1000000000) | P5: =IF(F5>0, SQRT((F5/MAX(F$5:F$886))^2 + (1 - H5/MAX(H$5:H$886))^2 + (J5/MAX(J$5:J$886))^2), 1000000000) | Q5: =IF(AND(ABS(B5-0.5)<0.01, ABS(C5-0.5)<0.01, ISNUMBER(SEARCH("Var", D5))), 1, 0) | R5: =IF(F5>0, J5, 1000000000) | S5: =IF(AND(F5<=DASHBOARD!$B$11, H5>=DASHBOARD!$B$13), G5, -1000000000000) | T5: =IF(AND(F5<=DASHBOARD!$B$11, H5>=DASHBOARD!$B$13), R5, 1000000000000) | U5: =IF(AND(F5<=DASHBOARD!$B$11, H5>=DASHBOARD!$B$13), N5, -1000000000000) | V5: =IF(AND(F5<=DASHBOARD!$B$11, H5>=DASHBOARD!$B$13), H5, -1000000000000) | W5: =IF(AND(F5<=DASHBOARD!$B$11, H5>=DASHBOARD!$B$13), K5, -1000000000000) | X5: =IF(AND(F5<=DASHBOARD!$B$11, H5>=DASHBOARD!$B$13), M5, 1000000000000) | Y5: =IF(AND(F5<=DASHBOARD!$B$10, H5>=DASHBOARD!$B$11), L5, 1000000000000) | Z5: =IF(AND(F5<=DASHBOARD!$B$10, H5>=DASHBOARD!$B$11), O5, 1000000000000) | AA5: =IF(AND(F5<=DASHBOARD!$B$10, H5>=DASHBOARD!$B$11), P5, 1000000000000) | AB5: =IF(AND(F5<=DASHBOARD!$B$10, H5>=DASHBOARD!$B$11), Q5, -1000000000000)
A6: 2 | B6: 0 | C6: 0 | D6: Var (%20) | E6: =IF((B6+C6)<=1, "Tam Mahsuplaşma (≤%100)", "Kısmi Satış (>%100)") | F6: =((VERI_TABANI!$D$29*B6/VERI_TABANI!$B$29)/VERI_TABANI!$B$3)*VERI_TABANI!$B$5 + ((VERI_TABANI!$D$29*C6/VERI_TABANI!$B$29)/VERI_TABANI!$B$4)*VERI_TABANI!$B$6 + IF(ISNUMBER(SEARCH("Var", D6)), (VERI_TABANI!$F$29/VERI_TABANI!$B$29)*(VERI_TABANI!$B$10+VERI_TABANI!$B$12), 0) | G6: =(((MIN(VERI_TABANI!D23, VERI_TABANI!D23*B6)*VERI_TABANI!$B$7 + MAX(0, VERI_TABANI!D23*B6-VERI_TABANI!D23)*VERI_TABANI!$B$8) + (MIN(MAX(0, VERI_TABANI!D23-VERI_TABANI!D23*B6), VERI_TABANI!D23*C6)*VERI_TABANI!$B$7 + MAX(0, VERI_TABANI!D23*C6-MAX(0, VERI_TABANI!D23-VERI_TABANI!D23*B6))*VERI_TABANI!$B$8) + IF(ABS(IF(ISNUMBER(SEARCH("Var", D6)), 1, IF(ISNUMBER(SEARCH("Gri", D6)), -1, 0)))=1, VERI_TABANI!E23*(1-0.928)*VERI_TABANI!$B$9, 0) + (VERI_TABANI!D23*B6*(VERI_TABANI!$B$13-VERI_TABANI!$B$14)*VERI_TABANI!G23) + (VERI_TABANI!D23*C6*(VERI_TABANI!$B$13-VERI_TABANI!$B$15)*VERI_TABANI!G23) + IF(ABS(IF(ISNUMBER(SEARCH("Var", D6)), 1, IF(ISNUMBER(SEARCH("Gri", D6)), -1, 0)))=1, VERI_TABANI!E23*(1-0.928)*0.00206091519919798*VERI_TABANI!G23, 0)) + ((MIN(VERI_TABANI!D24, VERI_TABANI!D24*B6)*VERI_TABANI!$B$7 + MAX(0, VERI_TABANI!D24*B6-VERI_TABANI!D24)*VERI_TABANI!$B$8) + (MIN(MAX(0, VERI_TABANI!D24-VERI_TABANI!D24*B6), VERI_TABANI!D24*C6)*VERI_TABANI!$B$7 + MAX(0, VERI_TABANI!D24*C6-MAX(0, VERI_TABANI!D24-VERI_TABANI!D24*B6))*VERI_TABANI!$B$8) + IF(ABS(IF(ISNUMBER(SEARCH("Var", D6)), 1, IF(ISNUMBER(SEARCH("Gri", D6)), -1, 0)))=1, VERI_TABANI!E24*(1-0.928)*VERI_TABANI!$B$9, 0) + (VERI_TABANI!D24*B6*(VERI_TABANI!$B$13-VERI_TABANI!$B$14)*VERI_TABANI!G24) + (VERI_TABANI!D24*C6*(VERI_TABANI!$B$13-VERI_TABANI!$B$15)*VERI_TABANI!G24) + IF(ABS(IF(ISNUMBER(SEARCH("Var", D6)), 1, IF(ISNUMBER(SEARCH("Gri", D6)), -1, 0)))=1, VERI_TABANI!E24*(1-0.928)*0.00206091519919798*VERI_TABANI!G24, 0)) + ((MIN(VERI_TABANI!D25, VERI_TABANI!D25*B6)*VERI_TABANI!$B$7 + MAX(0, VERI_TABANI!D25*B6-VERI_TABANI!D25)*VERI_TABANI!$B$8) + (MIN(MAX(0, VERI_TABANI!D25-VERI_TABANI!D25*B6), VERI_TABANI!D25*C6)*VERI_TABANI!$B$7 + MAX(0, VERI_TABANI!D25*C6-MAX(0, VERI_TABANI!D25-VERI_TABANI!D25*B6))*VERI_TABANI!$B$8) + IF(ABS(IF(ISNUMBER(SEARCH("Var", D6)), 1, IF(ISNUMBER(SEARCH("Gri", D6)), -1, 0)))=1, VERI_TABANI!E25*(1-0.928)*VERI_TABANI!$B$9, 0) + (VERI_TABANI!D25*B6*(VERI_TABANI!$B$13-VERI_TABANI!$B$14)*VERI_TABANI!G25) + (VERI_TABANI!D25*C6*(VERI_TABANI!$B$13-VERI_TABANI!$B$15)*VERI_TABANI!G25) + IF(ABS(IF(ISNUMBER(SEARCH("Var", D6)), 1, IF(ISNUMBER(SEARCH("Gri", D6)), -1, 0)))=1, VERI_TABANI!E25*(1-0.928)*0.00206091519919798*VERI_TABANI!G25, 0)) + ((MIN(VERI_TABANI!D26, VERI_TABANI!D26*B6)*VERI_TABANI!$B$7 + MAX(0, VERI_TABANI!D26*B6-VERI_TABANI!D26)*VERI_TABANI!$B$8) + (MIN(MAX(0, VERI_TABANI!D26-VERI_TABANI!D26*B6), VERI_TABANI!D26*C6)*VERI_TABANI!$B$7 + MAX(0, VERI_TABANI!D26*C6-MAX(0, VERI_TABANI!D26-VERI_TABANI!D26*B6))*VERI_TABANI!$B$8) + IF(ABS(IF(ISNUMBER(SEARCH("Var", D6)), 1, IF(ISNUMBER(SEARCH("Gri", D6)), -1, 0)))=1, VERI_TABANI!E26*(1-0.928)*VERI_TABANI!$B$9, 0) + (VERI_TABANI!D26*B6*(VERI_TABANI!$B$13-VERI_TABANI!$B$14)*VERI_TABANI!G26) + (VERI_TABANI!D26*C6*(VERI_TABANI!$B$13-VERI_TABANI!$B$15)*VERI_TABANI!G26) + IF(ABS(IF(ISNUMBER(SEARCH("Var", D6)), 1, IF(ISNUMBER(SEARCH("Gri", D6)), -1, 0)))=1, VERI_TABANI!E26*(1-0.928)*0.00206091519919798*VERI_TABANI!G26, 0)) + ((MIN(VERI_TABANI!D27, VERI_TABANI!D27*B6)*VERI_TABANI!$B$7 + MAX(0, VERI_TABANI!D27*B6-VERI_TABANI!D27)*VERI_TABANI!$B$8) + (MIN(MAX(0, VERI_TABANI!D27-VERI_TABANI!D27*B6), VERI_TABANI!D27*C6)*VERI_TABANI!$B$7 + MAX(0, VERI_TABANI!D27*C6-MAX(0, VERI_TABANI!D27-VERI_TABANI!D27*B6))*VERI_TABANI!$B$8) + IF(ABS(IF(ISNUMBER(SEARCH("Var", D6)), 1, IF(ISNUMBER(SEARCH("Gri", D6)), -1, 0)))=1, VERI_TABANI!E27*(1-0.928)*VERI_TABANI!$B$9, 0) + (VERI_TABANI!D27*B6*(VERI_TABANI!$B$13-VERI_TABANI!$B$14)*VERI_TABANI!G27) + (VERI_TABANI!D27*C6*(VERI_TABANI!$B$13-VERI_TABANI!$B$15)*VERI_TABANI!G27) + IF(ABS(IF(ISNUMBER(SEARCH("Var", D6)), 1, IF(ISNUMBER(SEARCH("Gri", D6)), -1, 0)))=1, VERI_TABANI!E27*(1-0.928)*0.00206091519919798*VERI_TABANI!G27, 0)) + ((MIN(VERI_TABANI!D28, VERI_TABANI!D28*B6)*VERI_TABANI!$B$7 + MAX(0, VERI_TABANI!D28*B6-VERI_TABANI!D28)*VERI_TABANI!$B$8) + (MIN(MAX(0, VERI_TABANI!D28-VERI_TABANI!D28*B6), VERI_TABANI!D28*C6)*VERI_TABANI!$B$7 + MAX(0, VERI_TABANI!D28*C6-MAX(0, VERI_TABANI!D28-VERI_TABANI!D28*B6))*VERI_TABANI!$B$8) + IF(ABS(IF(ISNUMBER(SEARCH("Var", D6)), 1, IF(ISNUMBER(SEARCH("Gri", D6)), -1, 0)))=1, VERI_TABANI!E28*(1-0.928)*VERI_TABANI!$B$9, 0) + (VERI_TABANI!D28*B6*(VERI_TABANI!$B$13-VERI_TABANI!$B$14)*VERI_TABANI!G28) + (VERI_TABANI!D28*C6*(VERI_TABANI!$B$13-VERI_TABANI!$B$15)*VERI_TABANI!G28) + IF(ABS(IF(ISNUMBER(SEARCH("Var", D6)), 1, IF(ISNUMBER(SEARCH("Gri", D6)), -1, 0)))=1, VERI_TABANI!E28*(1-0.928)*0.00206091519919798*VERI_TABANI!G28, 0))) | H6: =(((VERI_TABANI!D23*B6*(VERI_TABANI!$B$13-VERI_TABANI!$B$14)) + (VERI_TABANI!D23*C6*(VERI_TABANI!$B$13-VERI_TABANI!$B$15)) + IF(ISNUMBER(SEARCH("Var", D6)), VERI_TABANI!F23*(0.00202-VERI_TABANI!$B$16), IF(ISNUMBER(SEARCH("Gri", D6)), VERI_TABANI!F23*(0.00202-VERI_TABANI!$B$17), 0))) + ((VERI_TABANI!D24*B6*(VERI_TABANI!$B$13-VERI_TABANI!$B$14)) + (VERI_TABANI!D24*C6*(VERI_TABANI!$B$13-VERI_TABANI!$B$15)) + IF(ISNUMBER(SEARCH("Var", D6)), VERI_TABANI!F24*(0.00202-VERI_TABANI!$B$16), IF(ISNUMBER(SEARCH("Gri", D6)), VERI_TABANI!F24*(0.00202-VERI_TABANI!$B$17), 0))) + ((VERI_TABANI!D25*B6*(VERI_TABANI!$B$13-VERI_TABANI!$B$14)) + (VERI_TABANI!D25*C6*(VERI_TABANI!$B$13-VERI_TABANI!$B$15)) + IF(ISNUMBER(SEARCH("Var", D6)), VERI_TABANI!F25*(0.00202-VERI_TABANI!$B$16), IF(ISNUMBER(SEARCH("Gri", D6)), VERI_TABANI!F25*(0.00202-VERI_TABANI!$B$17), 0))) + ((VERI_TABANI!D26*B6*(VERI_TABANI!$B$13-VERI_TABANI!$B$14)) + (VERI_TABANI!D26*C6*(VERI_TABANI!$B$13-VERI_TABANI!$B$15)) + IF(ISNUMBER(SEARCH("Var", D6)), VERI_TABANI!F26*(0.00202-VERI_TABANI!$B$16), IF(ISNUMBER(SEARCH("Gri", D6)), VERI_TABANI!F26*(0.00202-VERI_TABANI!$B$17), 0))) + ((VERI_TABANI!D27*B6*(VERI_TABANI!$B$13-VERI_TABANI!$B$14)) + (VERI_TABANI!D27*C6*(VERI_TABANI!$B$13-VERI_TABANI!$B$15)) + IF(ISNUMBER(SEARCH("Var", D6)), VERI_TABANI!F27*(0.00202-VERI_TABANI!$B$16), IF(ISNUMBER(SEARCH("Gri", D6)), VERI_TABANI!F27*(0.00202-VERI_TABANI!$B$17), 0))) + ((VERI_TABANI!D28*B6*(VERI_TABANI!$B$13-VERI_TABANI!$B$14)) + (VERI_TABANI!D28*C6*(VERI_TABANI!$B$13-VERI_TABANI!$B$15)) + IF(ISNUMBER(SEARCH("Var", D6)), VERI_TABANI!F28*(0.00202-VERI_TABANI!$B$16), IF(ISNUMBER(SEARCH("Gri", D6)), VERI_TABANI!F28*(0.00202-VERI_TABANI!$B$17), 0)))) | I6: =IFERROR(((VERI_TABANI!$D$29*B6*VERI_TABANI!$B$14 + VERI_TABANI!$D$29*C6*VERI_TABANI!$B$15 + IF(ISNUMBER(SEARCH("Var", D6)), VERI_TABANI!$F$29*VERI_TABANI!$B$16, 0))) / (((VERI_TABANI!$D$29*B6 + VERI_TABANI!$D$29*C6)*VERI_TABANI!$B$13 + IF(ISNUMBER(SEARCH("Var", D6)), VERI_TABANI!$E$29*(1-0.928)*VERI_TABANI!$B$18, 0))), 0) | J6: =IFERROR(F6/(G6/29), 0) | K6: =IF(F6>0, H6/F6, 0) | L6: =IF(F6>0, I6, 1000000000) | M6: =ABS((B6+C6)-1) | N6: =IF(F6>0, (G6/29)/F6, 0) | O6: =IF(AND((B6+C6)>=1, ISNUMBER(SEARCH("Var", D6))), F6, 1000000000) | P6: =IF(F6>0, SQRT((F6/MAX(F$5:F$886))^2 + (1 - H6/MAX(H$5:H$886))^2 + (J6/MAX(J$5:J$886))^2), 1000000000) | Q6: =IF(AND(ABS(B6-0.5)<0.01, ABS(C6-0.5)<0.01, ISNUMBER(SEARCH("Var", D6))), 1, 0) | R6: =IF(F6>0, J6, 1000000000) | S6: =IF(AND(F6<=DASHBOARD!$B$11, H6>=DASHBOARD!$B$13), G6, -1000000000000) | T6: =IF(AND(F6<=DASHBOARD!$B$11, H6>=DASHBOARD!$B$13), R6, 1000000000000) | U6: =IF(AND(F6<=DASHBOARD!$B$11, H6>=DASHBOARD!$B$13), N6, -1000000000000) | V6: =IF(AND(F6<=DASHBOARD!$B$11, H6>=DASHBOARD!$B$13), H6, -1000000000000) | W6: =IF(AND(F6<=DASHBOARD!$B$11, H6>=DASHBOARD!$B$13), K6, -1000000000000) | X6: =IF(AND(F6<=DASHBOARD!$B$11, H6>=DASHBOARD!$B$13), M6, 1000000000000) | Y6: =IF(AND(F6<=DASHBOARD!$B$10, H6>=DASHBOARD!$B$11), L6, 1000000000000) | Z6: =IF(AND(F6<=DASHBOARD!$B$10, H6>=DASHBOARD!$B$11), O6, 1000000000000) | AA6: =IF(AND(F6<=DASHBOARD!$B$10, H6>=DASHBOARD!$B$11), P6, 1000000000000) | AB6: =IF(AND(F6<=DASHBOARD!$B$10, H6>=DASHBOARD!$B$11), Q6, -1000000000000)
A7: 3 | B7: 0 | C7: 0.1 | D7: Yok (%0) | E7: =IF((B7+C7)<=1, "Tam Mahsuplaşma (≤%100)", "Kısmi Satış (>%100)") | F7: =((VERI_TABANI!$D$29*B7/VERI_TABANI!$B$29)/VERI_TABANI!$B$3)*VERI_TABANI!$B$5 + ((VERI_TABANI!$D$29*C7/VERI_TABANI!$B$29)/VERI_TABANI!$B$4)*VERI_TABANI!$B$6 + IF(ISNUMBER(SEARCH("Var", D7)), (VERI_TABANI!$F$29/VERI_TABANI!$B$29)*(VERI_TABANI!$B$10+VERI_TABANI!$B$12), 0) | G7: =(((MIN(VERI_TABANI!D23, VERI_TABANI!D23*B7)*VERI_TABANI!$B$7 + MAX(0, VERI_TABANI!D23*B7-VERI_TABANI!D23)*VERI_TABANI!$B$8) + (MIN(MAX(0, VERI_TABANI!D23-VERI_TABANI!D23*B7), VERI_TABANI!D23*C7)*VERI_TABANI!$B$7 + MAX(0, VERI_TABANI!D23*C7-MAX(0, VERI_TABANI!D23-VERI_TABANI!D23*B7))*VERI_TABANI!$B$8) + IF(ABS(IF(ISNUMBER(SEARCH("Var", D7)), 1, IF(ISNUMBER(SEARCH("Gri", D7)), -1, 0)))=1, VERI_TABANI!E23*(1-0.928)*VERI_TABANI!$B$9, 0) + (VERI_TABANI!D23*B7*(VERI_TABANI!$B$13-VERI_TABANI!$B$14)*VERI_TABANI!G23) + (VERI_TABANI!D23*C7*(VERI_TABANI!$B$13-VERI_TABANI!$B$15)*VERI_TABANI!G23) + IF(ABS(IF(ISNUMBER(SEARCH("Var", D7)), 1, IF(ISNUMBER(SEARCH("Gri", D7)), -1, 0)))=1, VERI_TABANI!E23*(1-0.928)*0.00206091519919798*VERI_TABANI!G23, 0)) + ((MIN(VERI_TABANI!D24, VERI_TABANI!D24*B7)*VERI_TABANI!$B$7 + MAX(0, VERI_TABANI!D24*B7-VERI_TABANI!D24)*VERI_TABANI!$B$8) + (MIN(MAX(0, VERI_TABANI!D24-VERI_TABANI!D24*B7), VERI_TABANI!D24*C7)*VERI_TABANI!$B$7 + MAX(0, VERI_TABANI!D24*C7-MAX(0, VERI_TABANI!D24-VERI_TABANI!D24*B7))*VERI_TABANI!$B$8) + IF(ABS(IF(ISNUMBER(SEARCH("Var", D7)), 1, IF(ISNUMBER(SEARCH("Gri", D7)), -1, 0)))=1, VERI_TABANI!E24*(1-0.928)*VERI_TABANI!$B$9, 0) + (VERI_TABANI!D24*B7*(VERI_TABANI!$B$13-VERI_TABANI!$B$14)*VERI_TABANI!G24) + (VERI_TABANI!D24*C7*(VERI_TABANI!$B$13-VERI_TABANI!$B$15)*VERI_TABANI!G24) + IF(ABS(IF(ISNUMBER(SEARCH("Var", D7)), 1, IF(ISNUMBER(SEARCH("Gri", D7)), -1, 0)))=1, VERI_TABANI!E24*(1-0.928)*0.00206091519919798*VERI_TABANI!G24, 0)) + ((MIN(VERI_TABANI!D25, VERI_TABANI!D25*B7)*VERI_TABANI!$B$7 + MAX(0, VERI_TABANI!D25*B7-VERI_TABANI!D25)*VERI_TABANI!$B$8) + (MIN(MAX(0, VERI_TABANI!D25-VERI_TABANI!D25*B7), VERI_TABANI!D25*C7)*VERI_TABANI!$B$7 + MAX(0, VERI_TABANI!D25*C7-MAX(0, VERI_TABANI!D25-VERI_TABANI!D25*B7))*VERI_TABANI!$B$8) + IF(ABS(IF(ISNUMBER(SEARCH("Var", D7)), 1, IF(ISNUMBER(SEARCH("Gri", D7)), -1, 0)))=1, VERI_TABANI!E25*(1-0.928)*VERI_TABANI!$B$9, 0) + (VERI_TABANI!D25*B7*(VERI_TABANI!$B$13-VERI_TABANI!$B$14)*VERI_TABANI!G25) + (VERI_TABANI!D25*C7*(VERI_TABANI!$B$13-VERI_TABANI!$B$15)*VERI_TABANI!G25) + IF(ABS(IF(ISNUMBER(SEARCH("Var", D7)), 1, IF(ISNUMBER(SEARCH("Gri", D7)), -1, 0)))=1, VERI_TABANI!E25*(1-0.928)*0.00206091519919798*VERI_TABANI!G25, 0)) + ((MIN(VERI_TABANI!D26, VERI_TABANI!D26*B7)*VERI_TABANI!$B$7 + MAX(0, VERI_TABANI!D26*B7-VERI_TABANI!D26)*VERI_TABANI!$B$8) + (MIN(MAX(0, VERI_TABANI!D26-VERI_TABANI!D26*B7), VERI_TABANI!D26*C7)*VERI_TABANI!$B$7 + MAX(0, VERI_TABANI!D26*C7-MAX(0, VERI_TABANI!D26-VERI_TABANI!D26*B7))*VERI_TABANI!$B$8) + IF(ABS(IF(ISNUMBER(SEARCH("Var", D7)), 1, IF(ISNUMBER(SEARCH("Gri", D7)), -1, 0)))=1, VERI_TABANI!E26*(1-0.928)*VERI_TABANI!$B$9, 0) + (VERI_TABANI!D26*B7*(VERI_TABANI!$B$13-VERI_TABANI!$B$14)*VERI_TABANI!G26) + (VERI_TABANI!D26*C7*(VERI_TABANI!$B$13-VERI_TABANI!$B$15)*VERI_TABANI!G26) + IF(ABS(IF(ISNUMBER(SEARCH("Var", D7)), 1, IF(ISNUMBER(SEARCH("Gri", D7)), -1, 0)))=1, VERI_TABANI!E26*(1-0.928)*0.00206091519919798*VERI_TABANI!G26, 0)) + ((MIN(VERI_TABANI!D27, VERI_TABANI!D27*B7)*VERI_TABANI!$B$7 + MAX(0, VERI_TABANI!D27*B7-VERI_TABANI!D27)*VERI_TABANI!$B$8) + (MIN(MAX(0, VERI_TABANI!D27-VERI_TABANI!D27*B7), VERI_TABANI!D27*C7)*VERI_TABANI!$B$7 + MAX(0, VERI_TABANI!D27*C7-MAX(0, VERI_TABANI!D27-VERI_TABANI!D27*B7))*VERI_TABANI!$B$8) + IF(ABS(IF(ISNUMBER(SEARCH("Var", D7)), 1, IF(ISNUMBER(SEARCH("Gri", D7)), -1, 0)))=1, VERI_TABANI!E27*(1-0.928)*VERI_TABANI!$B$9, 0) + (VERI_TABANI!D27*B7*(VERI_TABANI!$B$13-VERI_TABANI!$B$14)*VERI_TABANI!G27) + (VERI_TABANI!D27*C7*(VERI_TABANI!$B$13-VERI_TABANI!$B$15)*VERI_TABANI!G27) + IF(ABS(IF(ISNUMBER(SEARCH("Var", D7)), 1, IF(ISNUMBER(SEARCH("Gri", D7)), -1, 0)))=1, VERI_TABANI!E27*(1-0.928)*0.00206091519919798*VERI_TABANI!G27, 0)) + ((MIN(VERI_TABANI!D28, VERI_TABANI!D28*B7)*VERI_TABANI!$B$7 + MAX(0, VERI_TABANI!D28*B7-VERI_TABANI!D28)*VERI_TABANI!$B$8) + (MIN(MAX(0, VERI_TABANI!D28-VERI_TABANI!D28*B7), VERI_TABANI!D28*C7)*VERI_TABANI!$B$7 + MAX(0, VERI_TABANI!D28*C7-MAX(0, VERI_TABANI!D28-VERI_TABANI!D28*B7))*VERI_TABANI!$B$8) + IF(ABS(IF(ISNUMBER(SEARCH("Var", D7)), 1, IF(ISNUMBER(SEARCH("Gri", D7)), -1, 0)))=1, VERI_TABANI!E28*(1-0.928)*VERI_TABANI!$B$9, 0) + (VERI_TABANI!D28*B7*(VERI_TABANI!$B$13-VERI_TABANI!$B$14)*VERI_TABANI!G28) + (VERI_TABANI!D28*C7*(VERI_TABANI!$B$13-VERI_TABANI!$B$15)*VERI_TABANI!G28) + IF(ABS(IF(ISNUMBER(SEARCH("Var", D7)), 1, IF(ISNUMBER(SEARCH("Gri", D7)), -1, 0)))=1, VERI_TABANI!E28*(1-0.928)*0.00206091519919798*VERI_TABANI!G28, 0))) | H7: =(((VERI_TABANI!D23*B7*(VERI_TABANI!$B$13-VERI_TABANI!$B$14)) + (VERI_TABANI!D23*C7*(VERI_TABANI!$B$13-VERI_TABANI!$B$15)) + IF(ISNUMBER(SEARCH("Var", D7)), VERI_TABANI!F23*(0.00202-VERI_TABANI!$B$16), IF(ISNUMBER(SEARCH("Gri", D7)), VERI_TABANI!F23*(0.00202-VERI_TABANI!$B$17), 0))) + ((VERI_TABANI!D24*B7*(VERI_TABANI!$B$13-VERI_TABANI!$B$14)) + (VERI_TABANI!D24*C7*(VERI_TABANI!$B$13-VERI_TABANI!$B$15)) + IF(ISNUMBER(SEARCH("Var", D7)), VERI_TABANI!F24*(0.00202-VERI_TABANI!$B$16), IF(ISNUMBER(SEARCH("Gri", D7)), VERI_TABANI!F24*(0.00202-VERI_TABANI!$B$17), 0))) + ((VERI_TABANI!D25*B7*(VERI_TABANI!$B$13-VERI_TABANI!$B$14)) + (VERI_TABANI!D25*C7*(VERI_TABANI!$B$13-VERI_TABANI!$B$15)) + IF(ISNUMBER(SEARCH("Var", D7)), VERI_TABANI!F25*(0.00202-VERI_TABANI!$B$16), IF(ISNUMBER(SEARCH("Gri", D7)), VERI_TABANI!F25*(0.00202-VERI_TABANI!$B$17), 0))) + ((VERI_TABANI!D26*B7*(VERI_TABANI!$B$13-VERI_TABANI!$B$14)) + (VERI_TABANI!D26*C7*(VERI_TABANI!$B$13-VERI_TABANI!$B$15)) + IF(ISNUMBER(SEARCH("Var", D7)), VERI_TABANI!F26*(0.00202-VERI_TABANI!$B$16), IF(ISNUMBER(SEARCH("Gri", D7)), VERI_TABANI!F26*(0.00202-VERI_TABANI!$B$17), 0))) + ((VERI_TABANI!D27*B7*(VERI_TABANI!$B$13-VERI_TABANI!$B$14)) + (VERI_TABANI!D27*C7*(VERI_TABANI!$B$13-VERI_TABANI!$B$15)) + IF(ISNUMBER(SEARCH("Var", D7)), VERI_TABANI!F27*(0.00202-VERI_TABANI!$B$16), IF(ISNUMBER(SEARCH("Gri", D7)), VERI_TABANI!F27*(0.00202-VERI_TABANI!$B$17), 0))) + ((VERI_TABANI!D28*B7*(VERI_TABANI!$B$13-VERI_TABANI!$B$14)) + (VERI_TABANI!D28*C7*(VERI_TABANI!$B$13-VERI_TABANI!$B$15)) + IF(ISNUMBER(SEARCH("Var", D7)), VERI_TABANI!F28*(0.00202-VERI_TABANI!$B$16), IF(ISNUMBER(SEARCH("Gri", D7)), VERI_TABANI!F28*(0.00202-VERI_TABANI!$B$17), 0)))) | I7: =IFERROR(((VERI_TABANI!$D$29*B7*VERI_TABANI!$B$14 + VERI_TABANI!$D$29*C7*VERI_TABANI!$B$15 + IF(ISNUMBER(SEARCH("Var", D7)), VERI_TABANI!$F$29*VERI_TABANI!$B$16, 0))) / (((VERI_TABANI!$D$29*B7 + VERI_TABANI!$D$29*C7)*VERI_TABANI!$B$13 + IF(ISNUMBER(SEARCH("Var", D7)), VERI_TABANI!$E$29*(1-0.928)*VERI_TABANI!$B$18, 0))), 0) | J7: =IFERROR(F7/(G7/29), 0) | K7: =IF(F7>0, H7/F7, 0) | L7: =IF(F7>0, I7, 1000000000) | M7: =ABS((B7+C7)-1) | N7: =IF(F7>0, (G7/29)/F7, 0) | O7: =IF(AND((B7+C7)>=1, ISNUMBER(SEARCH("Var", D7))), F7, 1000000000) | P7: =IF(F7>0, SQRT((F7/MAX(F$5:F$886))^2 + (1 - H7/MAX(H$5:H$886))^2 + (J7/MAX(J$5:J$886))^2), 1000000000) | Q7: =IF(AND(ABS(B7-0.5)<0.01, ABS(C7-0.5)<0.01, ISNUMBER(SEARCH("Var", D7))), 1, 0) | R7: =IF(F7>0, J7, 1000000000) | S7: =IF(AND(F7<=DASHBOARD!$B$11, H7>=DASHBOARD!$B$13), G7, -1000000000000) | T7: =IF(AND(F7<=DASHBOARD!$B$11, H7>=DASHBOARD!$B$13), R7, 1000000000000) | U7: =IF(AND(F7<=DASHBOARD!$B$11, H7>=DASHBOARD!$B$13), N7, -1000000000000) | V7: =IF(AND(F7<=DASHBOARD!$B$11, H7>=DASHBOARD!$B$13), H7, -1000000000000) | W7: =IF(AND(F7<=DASHBOARD!$B$11, H7>=DASHBOARD!$B$13), K7, -1000000000000) | X7: =IF(AND(F7<=DASHBOARD!$B$11, H7>=DASHBOARD!$B$13), M7, 1000000000000) | Y7: =IF(AND(F7<=DASHBOARD!$B$10, H7>=DASHBOARD!$B$11), L7, 1000000000000) | Z7: =IF(AND(F7<=DASHBOARD!$B$10, H7>=DASHBOARD!$B$11), O7, 1000000000000) | AA7: =IF(AND(F7<=DASHBOARD!$B$10, H7>=DASHBOARD!$B$11), P7, 1000000000000) | AB7: =IF(AND(F7<=DASHBOARD!$B$10, H7>=DASHBOARD!$B$11), Q7, -1000000000000)
A8: 4 | B8: 0 | C8: 0.1 | D8: Var (%20) | E8: =IF((B8+C8)<=1, "Tam Mahsuplaşma (≤%100)", "Kısmi Satış (>%100)") | F8: =((VERI_TABANI!$D$29*B8/VERI_TABANI!$B$29)/VERI_TABANI!$B$3)*VERI_TABANI!$B$5 + ((VERI_TABANI!$D$29*C8/VERI_TABANI!$B$29)/VERI_TABANI!$B$4)*VERI_TABANI!$B$6 + IF(ISNUMBER(SEARCH("Var", D8)), (VERI_TABANI!$F$29/VERI_TABANI!$B$29)*(VERI_TABANI!$B$10+VERI_TABANI!$B$12), 0) | G8: =(((MIN(VERI_TABANI!D23, VERI_TABANI!D23*B8)*VERI_TABANI!$B$7 + MAX(0, VERI_TABANI!D23*B8-VERI_TABANI!D23)*VERI_TABANI!$B$8) + (MIN(MAX(0, VERI_TABANI!D23-VERI_TABANI!D23*B8), VERI_TABANI!D23*C8)*VERI_TABANI!$B$7 + MAX(0, VERI_TABANI!D23*C8-MAX(0, VERI_TABANI!D23-VERI_TABANI!D23*B8))*VERI_TABANI!$B$8) + IF(ABS(IF(ISNUMBER(SEARCH("Var", D8)), 1, IF(ISNUMBER(SEARCH("Gri", D8)), -1, 0)))=1, VERI_TABANI!E23*(1-0.928)*VERI_TABANI!$B$9, 0) + (VERI_TABANI!D23*B8*(VERI_TABANI!$B$13-VERI_TABANI!$B$14)*VERI_TABANI!G23) + (VERI_TABANI!D23*C8*(VERI_TABANI!$B$13-VERI_TABANI!$B$15)*VERI_TABANI!G23) + IF(ABS(IF(ISNUMBER(SEARCH("Var", D8)), 1, IF(ISNUMBER(SEARCH("Gri", D8)), -1, 0)))=1, VERI_TABANI!E23*(1-0.928)*0.00206091519919798*VERI_TABANI!G23, 0)) + ((MIN(VERI_TABANI!D24, VERI_TABANI!D24*B8)*VERI_TABANI!$B$7 + MAX(0, VERI_TABANI!D24*B8-VERI_TABANI!D24)*VERI_TABANI!$B$8) + (MIN(MAX(0, VERI_TABANI!D24-VERI_TABANI!D24*B8), VERI_TABANI!D24*C8)*VERI_TABANI!$B$7 + MAX(0, VERI_TABANI!D24*C8-MAX(0, VERI_TABANI!D24-VERI_TABANI!D24*B8))*VERI_TABANI!$B$8) + IF(ABS(IF(ISNUMBER(SEARCH("Var", D8)), 1, IF(ISNUMBER(SEARCH("Gri", D8)), -1, 0)))=1, VERI_TABANI!E24*(1-0.928)*VERI_TABANI!$B$9, 0) + (VERI_TABANI!D24*B8*(VERI_TABANI!$B$13-VERI_TABANI!$B$14)*VERI_TABANI!G24) + (VERI_TABANI!D24*C8*(VERI_TABANI!$B$13-VERI_TABANI!$B$15)*VERI_TABANI!G24) + IF(ABS(IF(ISNUMBER(SEARCH("Var", D8)), 1, IF(ISNUMBER(SEARCH("Gri", D8)), -1, 0)))=1, VERI_TABANI!E24*(1-0.928)*0.00206091519919798*VERI_TABANI!G24, 0)) + ((MIN(VERI_TABANI!D25, VERI_TABANI!D25*B8)*VERI_TABANI!$B$7 + MAX(0, VERI_TABANI!D25*B8-VERI_TABANI!D25)*VERI_TABANI!$B$8) + (MIN(MAX(0, VERI_TABANI!D25-VERI_TABANI!D25*B8), VERI_TABANI!D25*C8)*VERI_TABANI!$B$7 + MAX(0, VERI_TABANI!D25*C8-MAX(0, VERI_TABANI!D25-VERI_TABANI!D25*B8))*VERI_TABANI!$B$8) + IF(ABS(IF(ISNUMBER(SEARCH("Var", D8)), 1, IF(ISNUMBER(SEARCH("Gri", D8)), -1, 0)))=1, VERI_TABANI!E25*(1-0.928)*VERI_TABANI!$B$9, 0) + (VERI_TABANI!D25*B8*(VERI_TABANI!$B$13-VERI_TABANI!$B$14)*VERI_TABANI!G25) + (VERI_TABANI!D25*C8*(VERI_TABANI!$B$13-VERI_TABANI!$B$15)*VERI_TABANI!G25) + IF(ABS(IF(ISNUMBER(SEARCH("Var", D8)), 1, IF(ISNUMBER(SEARCH("Gri", D8)), -1, 0)))=1, VERI_TABANI!E25*(1-0.928)*0.00206091519919798*VERI_TABANI!G25, 0)) + ((MIN(VERI_TABANI!D26, VERI_TABANI!D26*B8)*VERI_TABANI!$B$7 + MAX(0, VERI_TABANI!D26*B8-VERI_TABANI!D26)*VERI_TABANI!$B$8) + (MIN(MAX(0, VERI_TABANI!D26-VERI_TABANI!D26*B8), VERI_TABANI!D26*C8)*VERI_TABANI!$B$7 + MAX(0, VERI_TABANI!D26*C8-MAX(0, VERI_TABANI!D26-VERI_TABANI!D26*B8))*VERI_TABANI!$B$8) + IF(ABS(IF(ISNUMBER(SEARCH("Var", D8)), 1, IF(ISNUMBER(SEARCH("Gri", D8)), -1, 0)))=1, VERI_TABANI!E26*(1-0.928)*VERI_TABANI!$B$9, 0) + (VERI_TABANI!D26*B8*(VERI_TABANI!$B$13-VERI_TABANI!$B$14)*VERI_TABANI!G26) + (VERI_TABANI!D26*C8*(VERI_TABANI!$B$13-VERI_TABANI!$B$15)*VERI_TABANI!G26) + IF(ABS(IF(ISNUMBER(SEARCH("Var", D8)), 1, IF(ISNUMBER(SEARCH("Gri", D8)), -1, 0)))=1, VERI_TABANI!E26*(1-0.928)*0.00206091519919798*VERI_TABANI!G26, 0)) + ((MIN(VERI_TABANI!D27, VERI_TABANI!D27*B8)*VERI_TABANI!$B$7 + MAX(0, VERI_TABANI!D27*B8-VERI_TABANI!D27)*VERI_TABANI!$B$8) + (MIN(MAX(0, VERI_TABANI!D27-VERI_TABANI!D27*B8), VERI_TABANI!D27*C8)*VERI_TABANI!$B$7 + MAX(0, VERI_TABANI!D27*C8-MAX(0, VERI_TABANI!D27-VERI_TABANI!D27*B8))*VERI_TABANI!$B$8) + IF(ABS(IF(ISNUMBER(SEARCH("Var", D8)), 1, IF(ISNUMBER(SEARCH("Gri", D8)), -1, 0)))=1, VERI_TABANI!E27*(1-0.928)*VERI_TABANI!$B$9, 0) + (VERI_TABANI!D27*B8*(VERI_TABANI!$B$13-VERI_TABANI!$B$14)*VERI_TABANI!G27) + (VERI_TABANI!D27*C8*(VERI_TABANI!$B$13-VERI_TABANI!$B$15)*VERI_TABANI!G27) + IF(ABS(IF(ISNUMBER(SEARCH("Var", D8)), 1, IF(ISNUMBER(SEARCH("Gri", D8)), -1, 0)))=1, VERI_TABANI!E27*(1-0.928)*0.00206091519919798*VERI_TABANI!G27, 0)) + ((MIN(VERI_TABANI!D28, VERI_TABANI!D28*B8)*VERI_TABANI!$B$7 + MAX(0, VERI_TABANI!D28*B8-VERI_TABANI!D28)*VERI_TABANI!$B$8) + (MIN(MAX(0, VERI_TABANI!D28-VERI_TABANI!D28*B8), VERI_TABANI!D28*C8)*VERI_TABANI!$B$7 + MAX(0, VERI_TABANI!D28*C8-MAX(0, VERI_TABANI!D28-VERI_TABANI!D28*B8))*VERI_TABANI!$B$8) + IF(ABS(IF(ISNUMBER(SEARCH("Var", D8)), 1, IF(ISNUMBER(SEARCH("Gri", D8)), -1, 0)))=1, VERI_TABANI!E28*(1-0.928)*VERI_TABANI!$B$9, 0) + (VERI_TABANI!D28*B8*(VERI_TABANI!$B$13-VERI_TABANI!$B$14)*VERI_TABANI!G28) + (VERI_TABANI!D28*C8*(VERI_TABANI!$B$13-VERI_TABANI!$B$15)*VERI_TABANI!G28) + IF(ABS(IF(ISNUMBER(SEARCH("Var", D8)), 1, IF(ISNUMBER(SEARCH("Gri", D8)), -1, 0)))=1, VERI_TABANI!E28*(1-0.928)*0.00206091519919798*VERI_TABANI!G28, 0))) | H8: =(((VERI_TABANI!D23*B8*(VERI_TABANI!$B$13-VERI_TABANI!$B$14)) + (VERI_TABANI!D23*C8*(VERI_TABANI!$B$13-VERI_TABANI!$B$15)) + IF(ISNUMBER(SEARCH("Var", D8)), VERI_TABANI!F23*(0.00202-VERI_TABANI!$B$16), IF(ISNUMBER(SEARCH("Gri", D8)), VERI_TABANI!F23*(0.00202-VERI_TABANI!$B$17), 0))) + ((VERI_TABANI!D24*B8*(VERI_TABANI!$B$13-VERI_TABANI!$B$14)) + (VERI_TABANI!D24*C8*(VERI_TABANI!$B$13-VERI_TABANI!$B$15)) + IF(ISNUMBER(SEARCH("Var", D8)), VERI_TABANI!F24*(0.00202-VERI_TABANI!$B$16), IF(ISNUMBER(SEARCH("Gri", D8)), VERI_TABANI!F24*(0.00202-VERI_TABANI!$B$17), 0))) + ((VERI_TABANI!D25*B8*(VERI_TABANI!$B$13-VERI_TABANI!$B$14)) + (VERI_TABANI!D25*C8*(VERI_TABANI!$B$13-VERI_TABANI!$B$15)) + IF(ISNUMBER(SEARCH("Var", D8)), VERI_TABANI!F25*(0.00202-VERI_TABANI!$B$16), IF(ISNUMBER(SEARCH("Gri", D8)), VERI_TABANI!F25*(0.00202-VERI_TABANI!$B$17), 0))) + ((VERI_TABANI!D26*B8*(VERI_TABANI!$B$13-VERI_TABANI!$B$14)) + (VERI_TABANI!D26*C8*(VERI_TABANI!$B$13-VERI_TABANI!$B$15)) + IF(ISNUMBER(SEARCH("Var", D8)), VERI_TABANI!F26*(0.00202-VERI_TABANI!$B$16), IF(ISNUMBER(SEARCH("Gri", D8)), VERI_TABANI!F26*(0.00202-VERI_TABANI!$B$17), 0))) + ((VERI_TABANI!D27*B8*(VERI_TABANI!$B$13-VERI_TABANI!$B$14)) + (VERI_TABANI!D27*C8*(VERI_TABANI!$B$13-VERI_TABANI!$B$15)) + IF(ISNUMBER(SEARCH("Var", D8)), VERI_TABANI!F27*(0.00202-VERI_TABANI!$B$16), IF(ISNUMBER(SEARCH("Gri", D8)), VERI_TABANI!F27*(0.00202-VERI_TABANI!$B$17), 0))) + ((VERI_TABANI!D28*B8*(VERI_TABANI!$B$13-VERI_TABANI!$B$14)) + (VERI_TABANI!D28*C8*(VERI_TABANI!$B$13-VERI_TABANI!$B$15)) + IF(ISNUMBER(SEARCH("Var", D8)), VERI_TABANI!F28*(0.00202-VERI_TABANI!$B$16), IF(ISNUMBER(SEARCH("Gri", D8)), VERI_TABANI!F28*(0.00202-VERI_TABANI!$B$17), 0)))) | I8: =IFERROR(((VERI_TABANI!$D$29*B8*VERI_TABANI!$B$14 + VERI_TABANI!$D$29*C8*VERI_TABANI!$B$15 + IF(ISNUMBER(SEARCH("Var", D8)), VERI_TABANI!$F$29*VERI_TABANI!$B$16, 0))) / (((VERI_TABANI!$D$29*B8 + VERI_TABANI!$D$29*C8)*VERI_TABANI!$B$13 + IF(ISNUMBER(SEARCH("Var", D8)), VERI_TABANI!$E$29*(1-0.928)*VERI_TABANI!$B$18, 0))), 0) | J8: =IFERROR(F8/(G8/29), 0) | K8: =IF(F8>0, H8/F8, 0) | L8: =IF(F8>0, I8, 1000000000) | M8: =ABS((B8+C8)-1) | N8: =IF(F8>0, (G8/29)/F8, 0) | O8: =IF(AND((B8+C8)>=1, ISNUMBER(SEARCH("Var", D8))), F8, 1000000000) | P8: =IF(F8>0, SQRT((F8/MAX(F$5:F$886))^2 + (1 - H8/MAX(H$5:H$886))^2 + (J8/MAX(J$5:J$886))^2), 1000000000) | Q8: =IF(AND(ABS(B8-0.5)<0.01, ABS(C8-0.5)<0.01, ISNUMBER(SEARCH("Var", D8))), 1, 0) | R8: =IF(F8>0, J8, 1000000000) | S8: =IF(AND(F8<=DASHBOARD!$B$11, H8>=DASHBOARD!$B$13), G8, -1000000000000) | T8: =IF(AND(F8<=DASHBOARD!$B$11, H8>=DASHBOARD!$B$13), R8, 1000000000000) | U8: =IF(AND(F8<=DASHBOARD!$B$11, H8>=DASHBOARD!$B$13), N8, -1000000000000) | V8: =IF(AND(F8<=DASHBOARD!$B$11, H8>=DASHBOARD!$B$13), H8, -1000000000000) | W8: =IF(AND(F8<=DASHBOARD!$B$11, H8>=DASHBOARD!$B$13), K8, -1000000000000) | X8: =IF(AND(F8<=DASHBOARD!$B$11, H8>=DASHBOARD!$B$13), M8, 1000000000000) | Y8: =IF(AND(F8<=DASHBOARD!$B$10, H8>=DASHBOARD!$B$11), L8, 1000000000000) | Z8: =IF(AND(F8<=DASHBOARD!$B$10, H8>=DASHBOARD!$B$11), O8, 1000000000000) | AA8: =IF(AND(F8<=DASHBOARD!$B$10, H8>=DASHBOARD!$B$11), P8, 1000000000000) | AB8: =IF(AND(F8<=DASHBOARD!$B$10, H8>=DASHBOARD!$B$11), Q8, -1000000000000)
